[2021-03-13 22:07:33,374] {/Users/spencerb/cs411/application/venv/lib/python3.9/site-packages/flask/app.py:1891} ERROR - Exception on / [GET]
Traceback (most recent call last):
  File "/Users/spencerb/cs411/application/venv/lib/python3.9/site-packages/flask/app.py", line 2447, in wsgi_app
    response = self.full_dispatch_request()
  File "/Users/spencerb/cs411/application/venv/lib/python3.9/site-packages/flask/app.py", line 1952, in full_dispatch_request
    rv = self.handle_user_exception(e)
  File "/Users/spencerb/cs411/application/venv/lib/python3.9/site-packages/flask/app.py", line 1821, in handle_user_exception
    reraise(exc_type, exc_value, tb)
  File "/Users/spencerb/cs411/application/venv/lib/python3.9/site-packages/flask/_compat.py", line 39, in reraise
    raise value
  File "/Users/spencerb/cs411/application/venv/lib/python3.9/site-packages/flask/app.py", line 1950, in full_dispatch_request
    rv = self.dispatch_request()
  File "/Users/spencerb/cs411/application/venv/lib/python3.9/site-packages/flask/app.py", line 1936, in dispatch_request
    return self.view_functions[rule.endpoint](**req.view_args)
  File "/Users/spencerb/cs411/application/venv/lib/python3.9/site-packages/flask/views.py", line 89, in view
    return self.dispatch_request(*args, **kwargs)
  File "/Users/spencerb/cs411/application/venv/lib/python3.9/site-packages/flask/views.py", line 163, in dispatch_request
    return meth(*args, **kwargs)
  File "/Users/spencerb/cs411/application/main.py", line 12, in get
    return flask.render_template(page)
  File "/Users/spencerb/cs411/application/venv/lib/python3.9/site-packages/flask/templating.py", line 137, in render_template
    return _render(
  File "/Users/spencerb/cs411/application/venv/lib/python3.9/site-packages/flask/templating.py", line 120, in _render
    rv = template.render(context)
  File "/Users/spencerb/cs411/application/venv/lib/python3.9/site-packages/jinja2/environment.py", line 1090, in render
    self.environment.handle_exception()
  File "/Users/spencerb/cs411/application/venv/lib/python3.9/site-packages/jinja2/environment.py", line 832, in handle_exception
    reraise(*rewrite_traceback_stack(source=source))
  File "/Users/spencerb/cs411/application/venv/lib/python3.9/site-packages/jinja2/_compat.py", line 28, in reraise
    raise value.with_traceback(tb)
  File "/Users/spencerb/cs411/application/templates/index.html", line 1, in top-level template code
    {% extends "base.html" %}
  File "/Users/spencerb/cs411/application/venv/lib/python3.9/site-packages/flask/templating.py", line 60, in get_source
    return self._get_source_fast(environment, template)
  File "/Users/spencerb/cs411/application/venv/lib/python3.9/site-packages/flask/templating.py", line 89, in _get_source_fast
    raise TemplateNotFound(template)
jinja2.exceptions.TemplateNotFound: base.html
[2021-03-13 22:08:04,734] {/Users/spencerb/cs411/application/venv/lib/python3.9/site-packages/flask/app.py:1891} ERROR - Exception on / [GET]
Traceback (most recent call last):
  File "/Users/spencerb/cs411/application/venv/lib/python3.9/site-packages/flask/app.py", line 2447, in wsgi_app
    response = self.full_dispatch_request()
  File "/Users/spencerb/cs411/application/venv/lib/python3.9/site-packages/flask/app.py", line 1952, in full_dispatch_request
    rv = self.handle_user_exception(e)
  File "/Users/spencerb/cs411/application/venv/lib/python3.9/site-packages/flask/app.py", line 1821, in handle_user_exception
    reraise(exc_type, exc_value, tb)
  File "/Users/spencerb/cs411/application/venv/lib/python3.9/site-packages/flask/_compat.py", line 39, in reraise
    raise value
  File "/Users/spencerb/cs411/application/venv/lib/python3.9/site-packages/flask/app.py", line 1950, in full_dispatch_request
    rv = self.dispatch_request()
  File "/Users/spencerb/cs411/application/venv/lib/python3.9/site-packages/flask/app.py", line 1936, in dispatch_request
    return self.view_functions[rule.endpoint](**req.view_args)
  File "/Users/spencerb/cs411/application/venv/lib/python3.9/site-packages/flask/views.py", line 89, in view
    return self.dispatch_request(*args, **kwargs)
  File "/Users/spencerb/cs411/application/venv/lib/python3.9/site-packages/flask/views.py", line 163, in dispatch_request
    return meth(*args, **kwargs)
  File "/Users/spencerb/cs411/application/main.py", line 12, in get
    return flask.render_template(page)
  File "/Users/spencerb/cs411/application/venv/lib/python3.9/site-packages/flask/templating.py", line 137, in render_template
    return _render(
  File "/Users/spencerb/cs411/application/venv/lib/python3.9/site-packages/flask/templating.py", line 120, in _render
    rv = template.render(context)
  File "/Users/spencerb/cs411/application/venv/lib/python3.9/site-packages/jinja2/environment.py", line 1090, in render
    self.environment.handle_exception()
  File "/Users/spencerb/cs411/application/venv/lib/python3.9/site-packages/jinja2/environment.py", line 832, in handle_exception
    reraise(*rewrite_traceback_stack(source=source))
  File "/Users/spencerb/cs411/application/venv/lib/python3.9/site-packages/jinja2/_compat.py", line 28, in reraise
    raise value.with_traceback(tb)
  File "/Users/spencerb/cs411/application/templates/index.html", line 1, in top-level template code
    {% extends "base.html" %}
  File "/Users/spencerb/cs411/application/venv/lib/python3.9/site-packages/flask/templating.py", line 60, in get_source
    return self._get_source_fast(environment, template)
  File "/Users/spencerb/cs411/application/venv/lib/python3.9/site-packages/flask/templating.py", line 89, in _get_source_fast
    raise TemplateNotFound(template)
jinja2.exceptions.TemplateNotFound: base.html
